<?xml version="1.0" ?>
<sdf version="1.6">
  <model name="pollibee_drone">
    <link name="base_link">
      <inertial>
        <mass>0.270</mass>
        <inertia>
          <ixx>0.0002835</ixx>
          <iyy>0.0002835</iyy>
          <izz>0.0005625</izz>
          <ixy>0</ixy>
          <ixz>0</ixz>
          <iyz>0</iyz>
        </inertia>
      </inertial>

      <collision name="collision">
        <geometry>
          <box>
            <size>0.24 0.24 0.05</size>
          </box>
        </geometry>
      </collision>

      <visual name="visual">
        <geometry>
          <box>
            <size>0.24 0.24 0.05</size>
          </box>
        </geometry>
        <material>
          <script>
            <name>Gazebo/Yellow</name>
          </script>
        </material>
      </visual>

      <sensor name="camera" type="camera">
        <pose>0.12 0 0 0 0 0</pose>
        <camera>
          <horizontal_fov>1.085595</horizontal_fov>
          <image>
            <width>640</width>
            <height>480</height>
          </image>
          <clip>
            <near>0.1</near>
            <far>100</far>
          </clip>
        </camera>
        <always_on>1</always_on>
        <update_rate>30</update_rate>
        <visualize>true</visualize>
        <plugin name="camera_controller" filename="libgazebo_ros_camera.so">
          <alwaysOn>true</alwaysOn>
          <updateRate>30.0</updateRate>
          <cameraName>pollibee/camera</cameraName>
          <imageTopicName>image_raw</imageTopicName>
          <cameraInfoTopicName>camera_info</cameraInfoTopicName>
          <frameName>camera_link</frameName>
        </plugin>
      </sensor>
    </link>

    <link name="rotor_0">
      <pose>0.0707 -0.0707 0.025 0 0 0</pose>
      <inertial>
        <mass>0.01</mass>
        <inertia>
          <ixx>0.00001</ixx>
          <iyy>0.00001</iyy>
          <izz>0.00001</izz>
        </inertia>
      </inertial>
      <visual name="rotor_0_visual">
        <geometry>
          <cylinder>
            <radius>0.05</radius>
            <length>0.005</length>
          </cylinder>
        </geometry>
         <material>
          <script>
            <name>Gazebo/Blue</name>
          </script>
        </material>
      </visual>
    </link>

    <link name="rotor_1">
      <pose>-0.0707 0.0707 0.025 0 0 0</pose>
      <inertial>
        <mass>0.01</mass>
        <inertia>
          <ixx>0.00001</ixx>
          <iyy>0.00001</iyy>
          <izz>0.00001</izz>
        </inertia>
      </inertial>
      <visual name="rotor_1_visual">
        <geometry>
          <cylinder>
            <radius>0.05</radius>
            <length>0.005</length>
          </cylinder>
        </geometry>
        <material>
          <script>
            <name>Gazebo/Blue</name>
          </script>
        </material>
      </visual>
    </link>

    <link name="rotor_2">
      <pose>0.0707 0.0707 0.025 0 0 0</pose>
      <inertial>
        <mass>0.01</mass>
        <inertia>
          <ixx>0.00001</ixx>
          <iyy>0.00001</iyy>
          <izz>0.00001</izz>
        </inertia>
      </inertial>
      <visual name="rotor_2_visual">
        <geometry>
          <cylinder>
            <radius>0.05</radius>
            <length>0.005</length>
          </cylinder>
        </geometry>
        <material>
          <script>
            <name>Gazebo/Blue</name>
          </script>
        </material>
      </visual>
    </link>

    <link name="rotor_3">
      <pose>-0.0707 -0.0707 0.025 0 0 0</pose>
      <inertial>
        <mass>0.01</mass>
        <inertia>
          <ixx>0.00001</ixx>
          <iyy>0.00001</iyy>
          <izz>0.00001</izz>
        </inertia>
      </inertial>
      <visual name="rotor_3_visual">
        <geometry>
          <cylinder>
            <radius>0.05</radius>
            <length>0.005</length>
          </cylinder>
        </geometry>
        <material>
          <script>
            <name>Gazebo/Blue</name>
          </script>
        </material>
      </visual>
    </link>

    <joint name="joint_0" type="revolute">
      <pose>0.0707 -0.0707 0.025 0 0 0</pose>
      <child>rotor_0</child>
      <parent>base_link</parent>
      <axis>
        <xyz>0 0 1</xyz>
      </axis>
    </joint>

    <joint name="joint_1" type="revolute">
      <pose>-0.0707 0.0707 0.025 0 0 0</pose>
      <child>rotor_1</child>
      <parent>base_link</parent>
      <axis>
        <xyz>0 0 1</xyz>
      </axis>
    </joint>

    <joint name="joint_2" type="revolute">
      <pose>0.0707 0.0707 0.025 0 0 0</pose>
      <child>rotor_2</child>
      <parent>base_link</parent>
      <axis>
        <xyz>0 0 1</xyz>
      </axis>
    </joint>

    <joint name="joint_3" type="revolute">
      <pose>-0.0707 -0.0707 0.025 0 0 0</pose>
      <child>rotor_3</child>
      <parent>base_link</parent>
      <axis>
        <xyz>0 0 1</xyz>
      </axis>
    </joint>

    <link name="pollination_arm">
      <pose>0.12 0 0 0 0 0</pose>
      <inertial>
        <mass>0.05</mass>
        <inertia>
          <ixx>0.0001</ixx>
          <iyy>0.0001</iyy>
          <izz>0.0001</izz>
 <ixy>0</ixy>
          <ixz>0</ixz>
          <iyz>0</iyz>
        </inertia>
      </inertial>
      <visual name="pollination_arm_visual">
        <geometry>
          <box>
            <size>0.02 0.02 0.1</size>
          </box>
        </geometry>
        <material>
          <script>
            <name>Gazebo/Black</name>
          </script>
        </material>
      </visual>
    </link>

    <joint name="pollination_arm_joint" type="revolute">
      <pose>0.12 0 0 0 0 0</pose>
      <child>pollination_arm</child>
      <parent>base_link</parent>
      <axis>
        <xyz>0 0 1</xyz>
      </axis>
    </joint>

    <plugin name="gazebo_ros_control" filename="libgazebo_ros_control.so">
      <robotNamespace>/</robotNamespace>
    </plugin>

    <plugin name="gazebo_ros_motor" filename="libgazebo_ros_motor.so">
      <robotNamespace>/</robotNamespace>
      <motorName>motor_0</motorName>
      <jointName>joint_0</jointName>
    </plugin>

    <plugin name="gazebo_ros_motor" filename="libgazebo_ros_motor.so">
      <robotNamespace>/</robotNamespace>
      <motorName>motor_1</motorName>
      <jointName>joint_1</jointName>
    </plugin>

    <plugin name="gazebo_ros_motor" filename="libgazebo_ros_motor.so">
      <robotNamespace>/</robotNamespace>
      <motorName>motor_2</motorName>
      <jointName>joint_2</jointName>
    </plugin>

    <plugin name="gazebo_ros_motor" filename="libgazebo_ros_motor.so">
      <robotNamespace>/</robotNamespace>
      <motorName>motor_3</motorName>
      <jointName>joint_3</jointName>
    </plugin>

    <plugin name="gazebo_ros_motor" filename="libgazebo_ros_motor.so">
      <robotNamespace>/</robotNamespace>
      <motorName>pollination_motor</motorName>
      <jointName>pollination_arm_joint</jointName>
    </plugin>
  </model>
</sdf>
